Workbook

Sheet README
A1: Chin-Inlet EDF UAV Testbed - Purchasing Tracker
A3: HOW TO USE
A4: Fill in only the shaded yellow cells: Unit Price, Vendor, Order Date, Received.
A5: Line Total, and everything on the By Group tab, calculates itself.
A7: Set the Buy column to Yes once an item is ordered. The row turns green and
A8: the totals at the bottom of the Items tab update.
A10: Prices are deliberately left blank - fill in what you actually pay, including
A11: shipping and tax, so the totals reflect real spend rather than estimates.
A13: GROUPS
A14: A - Test stand and instrumentation. Needed for Phase 1.
A15: A2 - Pressure rake hardware. DEFERRED to Phase 3, months out.
A16: B - Propulsion. Needed for Phases 1-2.
... A39: +/-2% repeatability without it, you never needed it.

Sheet Items
B1: Group | C1: Item | D1: Specifics | E1: Qty | F1: Unit Price | G1: Line Total | H1: Vendor | I1: Order Date | J1: Received | K1: Notes
A2: Yes | B2: A - Test stand | C2: Load cell | D2: 10 kg straight bar, 4-wire full bridge | E2: 1 | F2: 24.33 | G2: =IF(F2="","",E2*F2) -> 24.33 | H2: SparkFun | I2: 46275 | J2: 46293 | K2: Usually sold bundled with HX711
A3: Yes | B3: A - Test stand | C3: HX711 breakout | D3: 24-bit ADC for load cell, run at 80 SPS | E3: 2 | F3: =6.99/2 -> 3.495 | G3: =IF(F3="","",E3*F3) -> 6.99 | H3: Amazon | I3: 46275 | J3: 46278 | K3: Often included in the load cell kit
A4: Yes | B4: A - Test stand | C4: Arduino Nano | D4: ATmega328P, USB-C or mini-B; clone is fine | E4: 3 | F4: =15.99/3 -> 5.33 | G4: =IF(F4="","",E4*F4) -> 15.99 | H4: Amazon | I4: 46275 | J4: 46278 | K4: Second board is a spare
A5: No | B5: A - Test stand | C5: INA226 module | D5: I2C current + voltage sensor, w/ shunt | E5: 2 | G5: =IF(F5="","",E5*F5) | K5: Logs electrical power
A6: Yes | B6: A - Test stand | C6: Digital multimeter | D6: Klein MM420 | E6: 1 | F6: 64.82 | G6: =IF(F6="","",E6*F6) -> 64.82 | H6: Amazon | I6: 46275 | J6: 46278 | K6: Own this one, don't borrow
A7: Yes | B7: A - Test stand | C7: Calibration mass set | D7: 100 g / 200 g / 500 g / 1 kg, +/-1% or better | E7: 1 | F7: 21.98 | G7: =IF(F7="","",E7*F7) -> 21.98 | H7: Amazon | I7: 46275 | J7: 46278 | K7: Accuracy floor for all thrust data
A8: Yes | B8: A - Test stand | C8: Thermo-hygrometer | D8: Digital, temperature + relative humidity, GOVEE H5075 | E8: 1 | F8: 12.99 | G8: =IF(F8="","",E8*F8) -> 12.99 | H8: Amazon | I8: 46275 | J8: 46278 | K8: Sits at the stand, not a phone app
A9: No | B9: A - Test stand | C9: C-clamps | D9: 4-6 inch throat | E9: 2 | G9: =IF(F9="","",E9*F9) | K9: Clamps baseplate to table
A10: No | B10: A - Test stand | C10: Solder | D10: Rosin core, 0.8 mm, 60/40 or lead-free | E10: 1 | G10: =IF(F10="","",E10*F10) | K10: Try ECE Supply Center first
A11: No | B11: A - Test stand | C11: Heat shrink assortment | D11: 1-6 mm diameters | E11: 1 | G11: =IF(F11="","",E11*F11) | K11: Try ECE Supply Center first
A12: No | B12: A - Test stand | C12: Hookup wire | D12: 22 AWG stranded, multiple colors | E12: 1 | G12: =IF(F12="","",E12*F12) | K12: Try ECE Supply Center first
A13: No | B13: A - Test stand | C13: Breadboard + jumper kit | D13: 830-point board, M-M and M-F jumpers | E13: 1 | G13: =IF(F13="","",E13*F13) | K13: Prototype before soldering
A14: No | B14: A - Test stand | C14: Plywood | D14: 3/4 inch, approx 400 x 250 mm offcut | E14: 1 | G14: =IF(F14="","",E14*F14) | K14: Baseplate; stiffness matters
A15: No | B15: A - Test stand | C15: Screws / standoffs / spacers | D15: M3 and M4 assortment, nylon + steel | E15: 1 | G15: =IF(F15="","",E15*F15) | K15: Spacers create the load cell air gap
A16: No | B16: A - Test stand | C16: Soldering iron + station | D16: Temperature controlled, 60W | E16: 1 | G16: =IF(F16="","",E16*F16) | K16: BORROW FIRST - only buy if shop hours block you
A17: No | B17: A2 - Rake (Phase 3) | C17: Sensirion SDP810-500Pa | D17: +/-500 Pa differential, I2C, sub-Pa resolution | E17: 1 | G17: =IF(F17="","",E17*F17) | K17: NOT MPXV7002DP - too coarse for 150-400 Pa signals
A18: No | B18: A2 - Rake (Phase 3) | C18: Pneumatic solenoid valve | D18: 3-way, 12 V, small port | E18: 8 | G18: =IF(F18="","",E18*F18) | K18: Multiplexes 8 tubes into 1 sensor
A19: No | B19: A2 - Rake (Phase 3) | C19: MOSFET driver board | D19: ULN2803 array or logic-level discretes | E19: 1 | G19: =IF(F19="","",E19*F19) | K19: Arduino drives the solenoids
A20: No | B20: A2 - Rake (Phase 3) | C20: Silicone tubing | D20: 2 mm ID, 5 m | E20: 1 | G20: =IF(F20="","",E20*F20) | K20: Cut all runs to EQUAL length
... A26: No | B26: B - Propulsion | C26: Hobbywing Platinum 120A V4 | D26: 6S ESC, 120 A continuous | E26: 1 | G26: =IF(F26="","",E26*F26) | K26: Mount in duct airflow
A27: Yes | B27: B - Propulsion | C27: LiPo pack | D27: 6S 22.2V 3300mAh, EC5 | E27: 2 | F27: =61.2 -> 61.2 | G27: =IF(F27="","",E27*F27) -> 122.4 | H27: Amazon | I27: 46275 | J27: 46279 | K27: Two in series = 12S later
A28: Yes | B28: B - Propulsion | C28: ISDT LiPo battery Charger MK2 | D28: 2x200W, 6s | E28: 1 | F28: 96 | G28: =IF(F28="","",E28*F28) -> 96 | H28: Amazon | I28: 46275 | J28: 46278 | K28: 2C charging keeps test days moving
A29: No | B29: B - Propulsion | C29: EC5 connector set | D29: Male + female pairs, main power | E29: 1 | G29: =IF(F29="","",E29*F29) | K29: XT90 rated 90 A
A30: No | B30: B - Propulsion | C30: Silicone wire | D30: 10 AWG, 3 m, red and black | E30: 1 | G30: =IF(F30="","",E30*F30) | K30: Sized for 100 A continuous
A31: No | B31: B - Propulsion | C31: Low-ESR capacitors | D31: 35 V, 470-1000 uF, on ESC leads | E31: 4 | G31: =IF(F31="","",E31*F31) | K31: Absorbs switching spikes from long leads
A32: No | B32: C - Airframe | C32: Matek F405-WING | D32: ArduPlane capable FC, onboard flash logging | E32: 1 | G32: =IF(F32="","",E32*F32) | K32: Used in manual passthrough as a logger
A33: No | B33: C - Airframe | C33: DLVR-L10D airspeed sensor | D33: Differential, low thermal drift, + pitot probe | E33: 1 | G33: =IF(F33="","",E33*F33) | K33: Preferred over MS4525DO
A34: No | B34: C - Airframe | C34: GPS / compass module | D34: M8N or newer | E34: 1 | G34: =IF(F34="","",E34*F34) | K34: Ground speed for wind correction
A35: No | B35: C - Airframe | C35: KST X10 servo | D35: Digital, metal gear, thin wing form factor | E35: 5 | G35: =IF(F35="","",E35*F35) | K35: MKS equivalent also fine
A36: No | B36: C - Airframe | C36: JP Hobby retract set | D36: 70 mm class, 3 units, alloy oleo struts | E36: 1 | G36: =IF(F36="","",E36*F36) | K36: Not nylon struts
A37: No | B37: C - Airframe | C37: Retract sequencer | D37: Electronic, 3 channel | E37: 1 | G37: =IF(F37="","",E37*F37) | K37: Skip if integrated in retract set
A38: No | B38: C - Airframe | C38: Switching BEC | D38: 8 A, 5-6 V output | E38: 1 | G38: =IF(F38="","",E38*F38) | K38: Separate from ESC linear BEC
A39: Yes | B39: C - Airframe | C39: RadioMaster ELRS ER8 reciever | D39: 2.4 GHz 8 ch ELRS PWM | E39: 1 | F39: 49.99 | G39: =IF(F39="","",E39*F39) -> 49.99 | H39: Amazon | I39: 46275 | J39: 46278 | K39: One spare - lost link at speed is total loss
A40: Yes | B40: C - Airframe | C40: RadioMaster TX16S MKII | D40: ELRS internal module, mode 2, w/ 5000 mAh battery | E40: 1 | F40: 271.99 | G40: =IF(F40="","",E40*F40) -> 271.99 | H40: Amazon | I40: 46275 | J40: 46295 | K40: Skip if you already own a transmitter
A41: No | B41: D - Materials | C41: LW-PLA filament | D41: Foaming lightweight PLA, 3 kg | E41: 1 | G41: =IF(F41="","",E41*F41) | K41: Airframe shells and wing skins
A42: No | B42: D - Materials | C42: PETG or ASA filament | D42: 1 kg | E42: 1 | G42: =IF(F42="","",E42*F42) | K42: Duct, nozzles, thrust tube, motor-adjacent
A43: No | B43: D - Materials | C43: PA-CF filament | D43: Carbon-filled nylon, 0.5 kg | E43: 1 | G43: =IF(F43="","",E43*F43) | K43: Gear mounts and hardpoints
A44: No | B44: D - Materials | C44: Carbon tube spars | D44: Pultruded, assorted diameters | E44: 1 | G44: =IF(F44="","",E44*F44) | K44: Carries wing bending, not printed structure
A45: No | B45: D - Materials | C45: Epoxy + filler primer + sandpaper | D45: Laminating epoxy, 400-1000 grit | E45: 1 | G45: =IF(F45="","",E45*F45) | K45: Duct interior finish converts to thrust
...

Sheet By Group
A1: Group | B1: Items | C1: Purchased | D1: Group Total | E1: Spent
A2: A - Test stand | B2: =COUNTIF(Items!$B$2:$B$54,$A2) -> 15 | C2: =COUNTIFS(Items!$B$2:$B$54,$A2,Items!$A$2:$A$54,"Yes") -> 6 | D2: =SUMIFS(Items!$G$2:$G$54,Items!$B$2:$B$54,$A2) -> 147.1 | E2: =SUMIFS(Items!$G$2:$G$54,Items!$B$2:$B$54,$A2,Items!$A$2:$A$54,"Yes") -> 147.1
A3: A2 - Rake (Phase 3) | B3: =COUNTIF(Items!$B$2:$B$54,$A3) -> 7 | C3: =COUNTIFS(Items!$B$2:$B$54,$A3,Items!$A$2:$A$54,"Yes") -> 0 | D3: =SUMIFS(Items!$G$2:$G$54,Items!$B$2:$B$54,$A3) -> 0 | E3: =SUMIFS(Items!$G$2:$G$54,Items!$B$2:$B$54,$A3,Items!$A$2:$A$54,"Yes") -> 0
A4: B - Propulsion | B4: =COUNTIF(Items!$B$2:$B$54,$A4) -> 8 | C4: =COUNTIFS(Items!$B$2:$B$54,$A4,Items!$A$2:$A$54,"Yes") -> 2 | D4: =SUMIFS(Items!$G$2:$G$54,Items!$B$2:$B$54,$A4) -> 218.4 | E4: =SUMIFS(Items!$G$2:$G$54,Items!$B$2:$B$54,$A4,Items!$A$2:$A$54,"Yes") -> 218.4
A5: C - Airframe | B5: =COUNTIF(Items!$B$2:$B$54,$A5) -> 9 | C5: =COUNTIFS(Items!$B$2:$B$54,$A5,Items!$A$2:$A$54,"Yes") -> 2 | D5: =SUMIFS(Items!$G$2:$G$54,Items!$B$2:$B$54,$A5) -> 321.98 | E5: =SUMIFS(Items!$G$2:$G$54,Items!$B$2:$B$54,$A5,Items!$A$2:$A$54,"Yes") -> 321.98
A6: D - Materials | B6: =COUNTIF(Items!$B$2:$B$54,$A6) -> 6 | C6: =COUNTIFS(Items!$B$2:$B$54,$A6,Items!$A$2:$A$54,"Yes") -> 0 | D6: =SUMIFS(Items!$G$2:$G$54,Items!$B$2:$B$54,$A6) -> 0 | E6: =SUMIFS(Items!$G$2:$G$54,Items!$B$2:$B$54,$A6,Items!$A$2:$A$54,"Yes") -> 0
A7: E - Trainer | B7: =COUNTIF(Items!$B$2:$B$54,$A7) -> 3 | C7: =COUNTIFS(Items!$B$2:$B$54,$A7,Items!$A$2:$A$54,"Yes") -> 2 | D7: =SUMIFS(Items!$G$2:$G$54,Items!$B$2:$B$54,$A7) -> 286.67 | E7: =SUMIFS(Items!$G$2:$G$54,Items!$B$2:$B$54,$A7,Items!$A$2:$A$54,"Yes") -> 286.67
A8: F - 12S upgrade | B8: =COUNTIF(Items!$B$2:$B$54,$A8) -> 4 | C8: =COUNTIFS(Items!$B$2:$B$54,$A8,Items!$A$2:$A$54,"Yes") -> 0 | D8: =SUMIFS(Items!$G$2:$G$54,Items!$B$2:$B$54,$A8) -> 0 | E8: =SUMIFS(Items!$G$2:$G$54,Items!$B$2:$B$54,$A8,Items!$A$2:$A$54,"Yes") -> 0
A9: TOTAL | B9: =SUM(B2:B8) -> 52 | C9: =SUM(C2:C8) -> 12 | D9: =SUM(D2:D8) -> 974.15 | E9: =SUM(E2:E8) -> 974.15
